Workbook

Sheet Tasks
A1: Task | B1: Instructions
A2: Build PivotTables and a Dashboard (including appropriate charts, slicer, and timeline) from the following pointers:
A3: 1 | B3: Product Performance | C3: Best/worst selling products
A4: 2 | C4: Product profitability analysis
A5: 3 | C5: Category-wise revenue distribution
A6: 4 | B6: Pricing Analysis | C6: Impact of discounts on sales volume
A7: 5 | C7: Price sensitivity by region
A8: 6 | C8: Optimal discount rates
A9: 7 | B9: Customer Behavior | C9: Rating patterns by product category
A10: 8 | C10: Purchase quantity trends
A11: 9 | C11: Seasonal buying patterns
A12: 10 | B12: Operational Insights | C12: High/low volume periods
A13: 11 | C13: Stock planning recommendations
A14: 12 | C14: City-wise market penetration
A15: 13 | B15: Cross-Analysis | C15: Category performance by region
A16: 14 | C16: Rating correlation with price points
A17: 15 | C17: Discount effectiveness by product type

Sheet pivot
B3: Product Performance
E5: Row Labels | F5: Sum of Quantity | H5: Row Labels | I5: Sum of Profite | K5: Row Labels | L5: Sum of Total_Price
E6: Cookbook | F6: 77 | H6: Shoes | I6: 16108.429 | K6: Books | L6: 59129.12
E7: Dress | F7: 74 | H7: Dress | I7: 15171.084 | K7: Clothing | L7: 76651.98
E8: T-Shirt | F8: 74 | H8: Cookbook | I8: 14972.449 | K8: Electronics | L8: 64505.49
E9: Smartphone | F9: 73 | H9: Plant Pot | I9: 14643.735 | K9: Home & Garden | L9: 52696.63
E10: Shoes | F10: 73 | H10: Smartphone | I10: 14107.827 | K10: Sports | L10: 43867.21
E11: Basketball | F11: 67 | H11: Jeans | I11: 12552.45 | K11: Grand Total | L11: 296850.43
E12: Smartwatch | F12: 66 | H12: Smartwatch | I12: 12151.472
E13: Plant Pot | F13: 61 | H13: Self-Help | I13: 11638.346
E14: Jacket | F14: 60 | H14: Jacket | I14: 9921.035 | K14: Sum of Quantity | L14: Sum of Discount
E15: Self-Help | F15: 58 | H15: Laptop | I15: 9537.43 | K15: 1349 | L15: 42.3
E16: Jeans | F16: 53 | H16: Tablet | I16: 9092.7895 | K16: Price Sensitivity by Region
E17: Running Shoes | F17: 53 | H17: Wall Art | I17: 8377.484 | K17: Row Labels | L17: Sum of Unit_Price | M17: Sum of Quantity
E18: Tablet | F18: 52 | H18: Basketball | I18: 8258.943 | K18: East | L18: 13137.28 | M18: 253
E19: Fiction | F19: 52 | H19: Fiction | I19: 7883.2155 | K19: North | L19: 17272.98 | M19: 382
E20: Dumbbells | F20: 51 | H20: Non-Fiction | I20: 7366.667 | K20: South | L20: 19251.91 | M20: 417
E21: Headphones | F21: 48 | H21: Lamp | I21: 7328.082 | K21: West | L21: 15164.95 | M21: 297
E22: Cushion | F22: 45 | H22: T-Shirt | I22: 7212.537 | K22: Grand Total | L22: 64827.12 | M22: 1349
E23: Tennis Racket | F23: 45 | H23: Dumbbells | I23: 7134.227
E24: Lamp | F24: 43 | H24: Running Shoes | I24: 7023.457 | K24: Optimal Discount Rates
E25: Wall Art | F25: 41 | H25: Headphones | I25: 6819.024 | K25: Row Labels | L25: Sum of Total_Price
E26: Non-Fiction | F26: 41 | H26: Rug | I26: 6688.609 | K26: 0 | L26: 83060.73
E27: Yoga Mat | F27: 39 | H27: Cushion | I27: 6608.2905 | K27: 0.1 | L27: 57085.08
E28: Laptop | F28: 39 | H28: Biography | I28: 6138.94 | K28: 0.2 | L28: 61618.9
E29: Rug | F29: 32 | H29: Tennis Racket | I29: 5813.975 | K29: 0.25 | L29: 50789.43
E30: Biography | F30: 32 | H30: Yoga Mat | I30: 5318.019 | K30: 0.3 | L30: 44296.29
E31: Grand Total | F31: 1349 | H31: Grand Total | I31: 237868.52 | K31: Grand Total | L31: 296850.43
C36: Row Labels | D36: Count of Customer_Rating | F36: Row Labels | G36: Count of Customer_Rating | I36: Row Labels | J36: Sum of Quantity | L36: Row Labels | M36: Sum of Total_Price | O36: Row Labels | P36: Sum of Unit_Price
C37: Books | D37: 49 | F37: Books | G37: 49 | I37: Mar | J37: 230 | L37: Mar | M37: 50954.41 | O37: 3 | P37: 14241.79
C38: Clothing | D38: 57 | F38: Clothing | G38: 57 | I38: Apr | J38: 193 | L38: Apr | M38: 48572.08 | O38: 4 | P38: 27901.2
C39: Electronics | D39: 49 | F39: Electronics | G39: 49 | I39: Jul | J39: 190 | L39: Jul | M39: 40898.07 | O39: 5 | P39: 22684.13
C40: Home & Garden | D40: 41 | F40: Home & Garden | G40: 41 | I40: Aug | J40: 184 | L40: Aug | M40: 40534.89 | O40: Grand Total | P40: 64827.12
C41: Sports | D41: 54 | F41: Sports | G41: 54 | I41: Jun | J41: 148 | L41: Jan | M41: 32395.63
C42: Grand Total | D42: 250 | F42: Grand Total | G42: 250 | I42: Jan | J42: 148 | L42: Jun | M42: 30008.49
I43: Feb | J43: 120 | L43: May | M43: 24505.06
I44: May | J44: 105 | L44: Feb | M44: 22347.88
I45: Sep | J45: 31 | L45: Sep | M45: 6633.92
C46: Row Labels | D46: Sum of Total_Price | I46: Grand Total | J46: 1349 | L46: Grand Total | M46: 296850.43
C47: Atlanta | D47: 39041.13
...

Sheet Dashbord
B2: Best/Worst Selling Products | J2: Seasonal Buying Patterns | O2: High/Low Volume Periods
B3: Best Selling | D3: Wrost Selling | J3: =pivot!L37 -> Mar | L3: =GETPIVOTDATA("Total_Price",pivot!$L$36,"Month","Mar") -> 50954.41 | O3: High | P3: =pivot!I37 -> Mar | Q3: =GETPIVOTDATA("Quantity",pivot!$I$36,"Months",3) -> 230
B4: =pivot!F62 -> Cookbook | C4: =GETPIVOTDATA("Quantity",pivot!$F$61,"Product","Cookbook") -> 77 | E4: =pivot!F86 -> Rug | F4: =GETPIVOTDATA("Quantity",pivot!$F$61,"Product","Rug") -> 32 | O4: Low | P4: =pivot!I45 -> Sep | Q4: =GETPIVOTDATA("Quantity",pivot!$I$36,"Months",9) -> 31
B7: Product profitability analysis | J7: Category-wise Revenue Distribution | Q7: Price Sensitivity by Region | Y7: City-wise Market Penetrationn
B24: Optimal Discount Rates | J24: Rating Patterns by Product Category | Q24: Purchase Quantity Trends | Y24: Purchase Quantity Trends
B42: Stock Planning Recommendations | J42: Category Performance by Region | R42: Rating Correlation with Price Points

Sheet Dataset
A1: Date | B1: Category | C1: Product | D1: Region | E1: City | F1: Quantity | G1: Unit_Price | H1: Discount | I1: Total_Price | J1: Customer_Rating | K1: Profite | L1: Month
A2: 44927 | B2: Books | C2: Non-Fiction | D2: South | E2: Atlanta | F2: 5 | G2: 377.29 | H2: 0 | I2: 1886.47 | J2: 5 | K2: =I2-(G2*F2*0.7) -> 565.955 | L2: =TEXT(A2,"MMM") -> Jan
A3: 44927 | B3: Electronics | C3: Smartwatch | D3: North | E3: New York | F3: 7 | G3: 399.2 | H3: 0 | I3: 2794.41 | J3: 5 | K3: =I3-(G3*F3*H3) -> 2794.41 | L3: =TEXT(A3,"MMM") -> Jan
A4: 44927 | B4: Sports | C4: Running Shoes | D4: East | E4: Baltimore | F4: 1 | G4: 309.2 | H4: 0.3 | I4: 216.44 | J4: 5 | K4: =I4-(G4*F4*H4) -> 123.68 | L4: =TEXT(A4,"MMM") -> Jan
A5: 44929 | B5: Books | C5: Biography | D5: North | E5: New York | F5: 8 | G5: 421.82 | H5: 0.2 | I5: 2699.62 | J5: 3 | K5: =I5-(G5*F5*H5) -> 2024.708 | L5: =TEXT(A5,"MMM") -> Jan
A6: 44929 | B6: Books | C6: Cookbook | D6: East | E6: Philadelphia | F6: 8 | G6: 415.69 | H6: 0.3 | I6: 2327.87 | J6: 5 | K6: =I6-(G6*F6*H6) -> 1330.214 | L6: =TEXT(A6,"MMM") -> Jan
A7: 44929 | B7: Sports | C7: Running Shoes | D7: North | E7: Chicago | F7: 9 | G7: 155.17 | H7: 0.3 | I7: 977.6 | J7: 3 | K7: =I7-(G7*F7*H7) -> 558.641 | L7: =TEXT(A7,"MMM") -> Jan
A8: 44932 | B8: Sports | C8: Yoga Mat | D8: South | E8: Miami | F8: 9 | G8: 299.08 | H8: 0.3 | I8: 1884.19 | J8: 5 | K8: =I8-(G8*F8*H8) -> 1076.674 | L8: =TEXT(A8,"MMM") -> Jan
A9: 44934 | B9: Home & Garden | C9: Plant Pot | D9: East | E9: Washington DC | F9: 4 | G9: 363.9 | H9: 0.1 | I9: 1310.05 | J9: 4 | K9: =I9-(G9*F9*H9) -> 1164.49 | L9: =TEXT(A9,"MMM") -> Jan
A10: 44935 | B10: Electronics | C10: Smartwatch | D10: South | E10: Atlanta | F10: 9 | G10: 181.11 | H10: 0.2 | I10: 1304.01 | J10: 4 | K10: =I10-(G10*F10*H10) -> 978.012 | L10: =TEXT(A10,"MMM") -> Jan
A11: 44936 | B11: Home & Garden | C11: Lamp | D11: South | E11: Atlanta | F11: 9 | G11: 159.34 | H11: 0.2 | I11: 1147.27 | J11: 3 | K11: =I11-(G11*F11*H11) -> 860.458 | L11: =TEXT(A11,"MMM") -> Jan
A12: 44941 | B12: Sports | C12: Dumbbells | D12: West | E12: San Francisco | F12: 5 | G12: 442.91 | H12: 0.25 | I12: 1660.92 | J12: 3 | K12: =I12-(G12*F12*H12) -> 1107.2825 | L12: =TEXT(A12,"MMM") -> Jan
A13: 44941 | B13: Electronics | C13: Smartphone | D13: South | E13: Atlanta | F13: 5 | G13: 22.92 | H13: 0 | I13: 114.6 | J13: 5 | K13: =I13-(G13*F13*H13) -> 114.6 | L13: =TEXT(A13,"MMM") -> Jan
A14: 44942 | B14: Sports | C14: Basketball | D14: North | E14: Chicago | F14: 5 | G14: 133.97 | H14: 0.2 | I14: 535.86 | J14: 4 | K14: =I14-(G14*F14*H14) -> 401.89 | L14: =TEXT(A14,"MMM") -> Jan
... A251: 45175 | B251: Books | C251: Fiction | D251: West | E251: Seattle | F251: 5 | G251: 451.2 | H251: 0.2 | I251: 1804.82 | J251: 3 | K251: =I251-(G251*F251*H251) -> 1353.62 | L251: =TEXT(A251,"MMM") -> Sep
